Workbook

Sheet Base_Original
A1: status | B1: nome | C1: cpf | D1: idade | E1: data_nascimento | F1: cidade | G1: regiao | H1: renda_mensal | I1: credito_tomado | J1: flag_inadimplente | K1: qtde_batalhas | L1: nivel_risco | M1: flag_inadimplente2 | N1: valor_solicitado
A2: Ativo | B2: Aegon Baelish | C2: 24000 | D2: 47 | E2: 29031 | F2: Meereen | Essos | H2: 28400 | I2: 78000 | J2: Não | K2: 37 | M2: Não | N2: 99000
A3: Ativo | B3: Aegon Blackwood | C3: 000.000.118-00 | D3: 69 | E3: 21054 | F3: Jardim de Cima | G3: Campina | H3: 23800 | I3: N/A | K3: 26 | N3: 89000
A4: Ativo | B4: Aegon Bracken | C4: 000.000.244-00 | D4: 69 | E4: 20725 | F4: Correrrio | G4: terras fluviais | H4: 8100 | I4: 27500 | J4: NÃO | K4: 42 | M4: NÃO | N4: 72500
A5: Inativo | B5: Aegon Florent | C5: 27100 | D5: 55 | E5: 25895 | F5: Meereen | G5: Essos | H5: 6800 | I5: 12000 | J5: Não | K5: 6 | M5: Não | N5: 11000 | Y5: =Base_Original!D2 -> 47
A6: Ativo | B6: Aegon Frey | C6: 000.000.338-00 | D6: 56 | E6: 25525 | F6: Dorne | G6: Dorne | H6: 11100 moedas | I6: 63000 | J6: Não | K6: 0 | M6: Não | N6: 56000
A7: Inativo | B7: Aegon Hornwood | C7: 17100 | D7: 45 | E7: 29506 | F7: Solar do Entardecer | G7: Terras da Tempestade | H7: 5100 | I7: 25000 | J7: Não | K7: 29 | M7: Não | N7: 88000
A8: Ativo | B8: Aegon Marbrand | C8: 35200 | D8: 65 | E8: 22337 | F8: Castelo Negro | G8: Norte | H8: 3800 | I8: 49500 | J8: Não | K8: 16 | M8: Não | N8: 15500
A9: Ativo | B9: Aegon Redwyne | C9: 000.000.347-00 | D9: 19 | E9: 39016 | F9: Pyke | G9: ILHAS DE FERRO | H9: 14900 | I9: 17000 | J9: Não | K9: 20 | M9: Não | N9: 29500
A10: Inativo | B10: Aegon Umber | C10: 000.000.356-00 | D10: 66 | E10: 22101 | F10: Meereen | G10: ESSOS | H10: 16800 | I10: 79500 | J10: Não | K10: 36 | M10: Não | N10: 1500
A11: Ativo | B11: Arya Marbrand | C11: 000.000.133-00 | D11: 24 | E11: 37172 | F11: Ninho da Águia | G11: Vale | H11: 21600 | I11: 25000 | J11: Não | K11: 33 | M11: Não | N11: 17500
A12: Ativo | B12: Arya Redwyne | C12: 000.000.333-00 | D12: 21 | E12: 38323 | F12: Correrrio | G12: Terras Fluviais | H12: 3800 moedas | I12: 0 | J12: Não | K12: 25 | M12: Não | N12: 50000
A13: inativo | B13: Asha Arryn | C13: 000.000.122-00 | D13: 49 | E13: 28049 | F13: Castelo Negro | G13: Norte | H13: 25200 | I13: 59500 | J13: Não | K13: 37 | M13: Não | N13: 86500
A14: Ativo | B14: Asha Baratheon | C14: 000.000.195-00 | D14: 70 | E14: 20570 | F14: Braavos | G14: Essos | H14: 16300 | I14: 16500 | J14: Não | K14: 25 | M14: Não | N14: 65500
A15: Ativo | B15: Asha Blackwood | C15: 000.000.085-00 | D15: 50 | E15: 27886 | F15: Dorne | G15: Dorne | H15: 16100 | I15: 8000 | J15: Sim | K15: 30 | M15: Sim | N15: 27000
A16: inativo | B16: Asha Bolton | C16: 6900 | D16: 51 | E16: 27590 | F16: Castelo Negro | G16: Norte | H16: 19400 | I16: 4000 | J16: Não | K16: 30 | M16: Não | N16: 38500
A17: Ativo | B17: Asha Hornwood | C17: 000.000.363-00 | D17: 33 | E17: 34144 | F17: Pedra do Dragão | G17: Terras da Coroa | H17: 21500 moedas | I17: N/A | J17: não | K17: 22 | M17: não | N17: 51500
A18: Inativo | B18: Asha Manderly | C18: 000.000.357-00 | D18: 29 | E18: 35607 | F18: Ilha dos Ursos | G18: Norte | H18: 13800 | I18: 41500 | J18: Não | K18: 34 | M18: Não | N18: 66000
A19: ATIVO | B19: Asha Redwyne | C19: 10200 | D19: 35 | E19: 33444 | F19: Pedra do Dragão | G19: Terras da Coroa | H19: 8400 | I19: 62500 | J19: Não | K19: 31 | M19: Não | N19: 83500
A20: Ativo | B20: Asha Tallhart | C20: 8600 | E20: 32260 | F20: Pyke | G20: Ilhas de Ferro | H20: 17600 moedas | I20: 0 | J20: Sim | K20: 31 | M20: Sim | N20: 47500
A21: Ativo | B21: Asha Tallhart | C21: 000.000.006-00 | D21: 59 | E21: 24710 | F21: Correrrio | Terras Fluviais | H21: 19900 | I21: 55000 | J21: Não | K21: 26 | M21: Não | N21: 100000
A22: Ativo | B22: Beric Karstark | C22: 000.000.172-00 | D22: 37 | E22: 32680 | F22: Braavos | G22: Essos | H22: 28900 | I22: 71000 | J22: Não | K22: 28 | M22: Não | N22: 36500
A23: Ativo | B23: Beric Umber | D23: 73 | E23: 19538 | F23: Pedra do Dragão | G23: terras da coroa | H23: 12700 | I23: 79500 | J23: Não | K23: 35 | M23: Não | N23: 39000
A24: Ativo | B24: BERIC CRAKEHALL | C24: 000.000.067-00 | D24: 55 | E24: 26104 | F24: Pyke | G24: Ilhas De Ferro | H24: 22100 | I24: 41500 | J24: Não | K24: 18 | M24: Não | N24: 65000
A25: Inativo | B25: Beric Manderly | C25: 24300 | D25: 25 | E25: 37131 | F25: Lannisporto | G25: Oeste | H25: 24500 | I25: N/A | J25: 0 | K25: 0 | M25: 0 | N25: 55000
A26: Ativo | B26: Beric Seaworth | C26: 000.000.025-00 | D26: 72 | E26: 19800 | F26: Correrrio | G26: Terras Fluviais | H26: 24300 | I26: 13500 | J26: Não | K26: 33 | M26: Não | N26: 14500
A27: Inativo | B27: Beric Tallhart | C27: 000.000.291-00 | D27: 44 | E27: 29948 | F27: Dorne | G27: Dorne | I27: 0 | J27: Não | K27: 4 | M27: Não | N27: 80000
A28: Ativo | B28: Beric Tyrell | C28: 000.000.103-00 | D28: 20 | E28: 38957 | F28: Fosso Cailin | G28: Norte | H28: 18200 | J28: Não | K28: 21 | M28: Não | N28: 61500
A29: Ativo | B29: Beric Tyrell | C29: 000.000.242-00 | D29: 66 | E29: 22151 | F29: Vilavelha | G29: Campina | H29: 11800 | I29: 2000 | J29: Sim | K29: 23 | M29: Sim | N29: 72500
A30: Ativo | B30: BRAN BOLTON | C30: 000.000.003-00 | D30: 23 | E30: 37785 | F30: Porto Real | G30: Terras Da Coroa | H30: 17900 | I30: 28000 | J30: Não | K30: 41 | M30: Não | N30: 52500
A31: Ativo | B31: Bran Dayne | C31: 000.000.288-00 | D31: 48 | E31: 28430 | F31: Pyke | G31: Ilhas De Ferro | H31: 4500 moedas | I31: 0 | J31: Não | K31: 3 | M31: Não | N31: 48500
A32: Ativo | B32: Bran Dondarrion | C32: 4900 | D32: 18 | E32: 39369 | F32: Meereen | G32: essos | H32: 18500 | I32: 74500 | J32: Sim | K32: 20 | M32: Sim | N32: 45500
A33: Ativo | B33: bran florent | C33: 000.000.218-00 | D33: 62 | E33: 23488 | F33: Ninho da Águia | G33: Vale | H33: sem renda | I33: N/A | J33: Não | K33: 38 batalhas | M33: Não | N33: 72000
A34: Ativo | B34: Bran Frey | C34: 000.000.189-00 | D34: 39 | E34: 31968 | F34: Ilha dos Ursos | Norte | H34: 8000 | I34: 69000 | J34: Não | K34: 15 | M34: Não | N34: 39500
A35: Inativo | B35: Bran Karstark | C35: 000.000.241-00 | D35: 21 | E35: 38328 | F35: Pyke | G35: ILHAS DE FERRO | H35: 4400 | I35: 23500 | J35: Sim | K35: 31 | M35: Sim | N35: 91000
A36: Ativo | B36: Bran Tarly | C36: 000.000.269-00 | D36: 53 | E36: 26790 | F36: Braavos | G36: Essos | H36: sem renda | I36: 21500 | J36: Sim | K36: 44 | M36: Sim | N36: 3500
A37: Ativo | B37: Bran Umber | C37: 13200 | D37: 29 | E37: 35334 | F37: Pyke | G37: Ilhas de Ferro | H37: 19500 | I37: 57000 | J37: Não | K37: 12 | M37: Não | N37: 20500
A38: Ativo | B38: Bran Yronwood | C38: 000.000.057-00 | D38: 42 | E38: 30878 | F38: Pyke | G38: Ilhas de Ferro | H38: 17500 | I38: 3500 | J38: Nao | K38: 25 | M38: Nao | N38: 35000
A39: Ativo | B39: Brienne Dayne | C39: 000.000.070-00 | D39: 62 | E39: 23337 | F39: Pedra do Dragão | G39: Terras da Coroa | H39: 11900 | I39: 58500 | J39: Não | K39: 37 | M39: Não | N39: 48000
A40: Ativo | B40: Brienne Dondarrion | C40: 000.000.256-00 | D40: 39 | E40: 31814 | F40: Ilha dos Ursos | G40: Norte | H40: 9300 | I40: 36500 | J40: Não | M40: Não | N40: 3000
...

Sheet Auditoria
A1: Auditoria de Qualidade dos Dados
A2: Coluna analisada | B2: Valor encontrado | C2: Quantidade | D2: Problema identificado | E2: Ação | F2: Impacto
A3: Status | B3: ATIVO | C3: 12 | D3: Capitalização inconsistente | E3: Padronizar → Ativo | F3: Baixo
A4: Status | B4: ativo | C4: 4 | D4: Capitalização inconsistente | E4: Padronizar → Ativo | F4: Baixo
A5: Status | B5: INATIVO | C5: 1 | D5: Capitalização inconsistente | E5: Padronizar → Inativo | F5: Baixo
A6: Status | B6: inativo | C6: 3 | D6: Capitalização inconsistente | E6: Padronizar → Inativo | F6: Baixo
A7: Status | B7: Ativo | C7: 245 | D7: Valor no padrão esperado | E7: Manter | F7: N/A
A8: Status | B8: Inativo | C8: 89 | D8: Valor no padrão esperado | E8: Manter | F8: N/A
A9: Status | B9: Ativoo | C9: 8 | D9: Possível erro de digitação / categoria inconsistente | E9: Validar dado | F9: Alto
A10: Status | B10: loqueado | C10: 1 | D10: Categoria não prevista / possível erro de digitação | E10: Validar dado | F10: Alto
A11: Status | B11: Vazio | C11: 4 | D11: Dado ausente | E11: Validar dado | F11: Alto
A12: Nome | B12: Nomes em minúsculas | C12: 17 | D12: Capitalização inconsistente | E12: Padronizar → Primeira letra maiúscula | F12: Baixo
A13: Nome | B13: Nomes em maiúsculas | C13: 21 | D13: Capitalização inconsistente | E13: Padronizar → Primeira letra maiúscula | F13: Baixo
A14: Idade | B14: Idades vazias | C14: 19 | D14: Dado ausente | E14: Validar dado | F14: Médio
... A29: Credito_Tomado | B29: X moedas | C29: 26 | D29: Valor numérico acompanhado de unidade textual | E29: Padronizar → número | F29: Alto
A30: Credito_Tomado | B30: 0 | C30: 42 | D30: Crédito tomado igual a zero | E30: Manter / investigar | F30: Médio
A31: Credito_Tomado | B31: Valores negativos | C31: 0 | D31: Nenhuma inconsistência encontrada | E31: Manter | F31: N/A
A32: Credito_Tomado | B32: Valores extremos | C32: 0 | D32: Nenhum valor extremo identificado | E32: Manter | F32: N/A
A33: Flag_Inadimplente | B33: não | C33: 7 | D33: Capitalização inconsistente | E33: Padronizar → Não | F33: Alto
A34: Flag_Inadimplente | B34: Não | C34: 241 | D34: Valor no padrão esperado | E34: Manter | F34: N/A
A35: Flag_Inadimplente | B35: Nao | C35: 15 | D35: Ausência de acentuação | E35: Padronizar → Não | F35: Alto
A36: Flag_Inadimplente | B36: NÃO | C36: 13 | D36: Capitalização inconsistente | E36: Padronizar → Não | F36: Alto
A37: Flag_Inadimplente | B37: sim | C37: 6 | D37: Capitalização inconsistente | E37: Padronizar → Sim | F37: Alto
A38: Flag_Inadimplente | B38: Sim | C38: 66 | D38: Valor no padrão esperado | E38: Manter | F38: N/A
A39: Flag_Inadimplente | B39: SIM | C39: 1 | D39: Capitalização inconsistente | E39: Padronizar → Sim | F39: Alto
A40: Flag_Inadimplente | B40: 0 | C40: 7 | D40: Categoria numérica não padronizada | E40: Validar dado | F40: Alto
A41: Flag_Inadimplente | B41: 1 | C41: 3 | D41: Categoria numérica não padronizada | E41: Validar dado | F41: Alto
A42: Flag_Inadimplente | B42: Vazio | C42: 10 | D42: Dado ausente | E42: Validar dado | F42: Alto
A43: Quantidade_Batalhas | B43: X batalhas | C43: 33 | D43: Valor numérico acompanhado de unidade textual | E43: Padronizar → número | F43: Médio
A44: Quantidade_Batalhas | B44: 0 | C44: 7 | D44: Valor válido possível | E44: Manter | F44: N/A
A45: Quantidade_Batalhas | B45: Vazio | C45: 4 | D45: Dado ausente | E45: Validar dado | F45: Médio
A46: Quantidade_Batalhas | B46: Valores negativos | C46: 0 | D46: Nenhuma inconsistência encontrada | E46: Manter | F46: N/A
A47: Quantidade_Batalhas | B47: Valores extremos | C47: 0 | D47: Nenhum valor extremo identificado | E47: Manter | F47: N/A
A48: Valor_Solicitado | B48: Valores vazios | C48: 0 | D48: Nenhuma inconsistência encontrada | E48: Manter | F48: N/A
A49: Valor_Solicitado | B49: Valores negativos | C49: 0 | D49: Nenhuma inconsistência encontrada | E49: Manter | F49: N/A
A50: Valor_Solicitado | B50: Valores iguais a zero | C50: 0 | D50: Nenhuma inconsistência encontrada | E50: Manter | F50: N/A
A51: Valor_Solicitado | B51: Valores não numéricos | C51: 0 | D51: Nenhuma inconsistência encontrada | E51: Manter | F51: N/A
A52: Valor_Solicitado | B52: Formatos diferentes | C52: 0 | D52: Nenhuma inconsistência encontrada | E52: Manter | F52: N/A

Sheet Base_Tratada
A1: ID_Solicitação | B1: Status_Padronizado | C1: Nome_Padronizado | D1: CPF | E1: CPF_Validação | F1: CPF_Duplicado | G1: Idade_Padronizada | H1: Idade_Validação | I1: Idade_Conferência | J1: Data_Nascimento | K1: Cidade_Padronizada | L1: Regiao_Padronizada | M1: Renda_Padronizada | N1: Credito_Tomado_Padronizado | O1: Analise_Credito | P1: Liberação_Credito | Q1: Flag_Inadimplente_Padronizada | R1: Quantidade_Batalhas_Padronizada | S1: Nivel_Risco | T1: Analise_Risco | U1: Valor_Solicitado_Padronizado
A2: SOL001 | B2: =IF(Base_Original!A2="","vazio",IF(Base_Original!A2="ATIVO","Ativo",IF(Base_Original!A2="INATIVO","Inativo",Base_Original!A2))) -> Ativo | C2: =PROPER(Base_Original!B2) -> Aegon Baelish | D2: 24000 | E2: =IF($D2="","Vazio",IF(LEN(SUBSTITUTE(SUBSTITUTE($D2&"",".",""),"-",""))<>11,"Inválido","OK")) -> Inválido | F2: =IF($D2="","Vazio",IF(COUNTIF($D$2:$D$369,$D2)>1,"Duplicado","Único")) -> Único | G2: =IF(TRIM(Base_Original!D2)="","",SUBSTITUTE(TRIM(Base_Original!D2),"anos","")) -> 47 | H2: =IF(Tabela2[[#This Row],[Data_Nascimento]]="","Vazio",IF(Tabela2[[#This Row],[Idade_Padronizada]]="","Sem idade",DATEDIF(Tabela2[[#This Row],[Data_Nascimento]],TODAY(),"Y"))) -> 47 | I2: =IF(OR(Tabela2[[#This Row],[Idade_Padronizada]]="",Tabela2[[#This Row],[Idade_Validação]]=""),"Vazio",IF(VALUE(Tabela2[[#This Row],[Idade_Padronizada]]&"")=VALUE(Tabela2[[#This Row],[Idade_Validação]]&""),"OK","Diferente")) -> OK | J2: 29031 | K2: Meereen | Essos | L2: =PROPER(Base_Original!G2) | M2: 28400 | N2: =IF(ISNUMBER(Base_Original!I2),Base_Original!I2,IF(RIGHT(Base_Original!I2,7)=" moedas",VALUE(LEFT(Base_Original!I2,LEN(Base_Original!I2)-7)),Base_Original!I2)) -> 78000 | O2: =IF(AND($N2>50000,$Q2="Sim"),"Negada","Aprovada") -> Aprovada | P2: =IF(AND($T2="Negada",$O2="Negada"),0,IF($B2="Ativo",$U2*8%,"0")) -> 7920 | Q2: =IF(OR(Base_Original!J2="Sim",Base_Original!J2="sim",Base_Original!J2="SIM"),"Sim",IF(OR(Base_Original!J2="Não",Base_Original!J2="não",Base_Original!J2="NÃO",Base_Original!J2="Nao"),"Não",IF(Base_Original!J2="","vazio",Base_Original!J2))) -> Não | R2: =IF(ISNUMBER(Base_Original!K2),Base_Original!K2,IF(RIGHT(Base_Original!K2,9)=" batalhas",VALUE(LEFT(Base_Original!K2,LEN(Base_Original!K2)-9)),Base_Original!K2)) -> 37 | S2: =IF($R2="vazio","vazio",IF($R2<=10,"Baixo",IF($R2<=25,"Médio","Alto"))) -> Alto | T2: =IF(AND($S2="Alto",$Q2="Sim"),"Negada","Aprovada") -> Aprovada | U2: 99000
A3: SOL002 | B3: =IF(Base_Original!A3="","vazio",IF(Base_Original!A3="ATIVO","Ativo",IF(Base_Original!A3="INATIVO","Inativo",Base_Original!A3))) -> Ativo | C3: =PROPER(Base_Original!B3) -> Aegon Blackwood | D3: 000.000.118-00 | E3: =IF($D3="","Vazio",IF(LEN(SUBSTITUTE(SUBSTITUTE($D3&"",".",""),"-",""))<>11,"Inválido","OK")) -> OK | F3: =IF($D3="","Vazio",IF(COUNTIF($D$2:$D$369,$D3)>1,"Duplicado","Único")) -> Único | G3: =IF(TRIM(Base_Original!D3)="","",SUBSTITUTE(TRIM(Base_Original!D3),"anos","")) -> 69 | H3: =IF(Tabela2[[#This Row],[Data_Nascimento]]="","Vazio",IF(Tabela2[[#This Row],[Idade_Padronizada]]="","Sem idade",DATEDIF(Tabela2[[#This Row],[Data_Nascimento]],TODAY(),"Y"))) -> 69 | I3: =IF(OR(Tabela2[[#This Row],[Idade_Padronizada]]="",Tabela2[[#This Row],[Idade_Validação]]=""),"Vazio",IF(VALUE(Tabela2[[#This Row],[Idade_Padronizada]]&"")=VALUE(Tabela2[[#This Row],[Idade_Validação]]&""),"OK","Diferente")) -> OK | J3: 21054 | K3: Jardim de Cima | L3: =PROPER(Base_Original!G3) -> Campina | M3: 23800 | N3: =IF(ISNUMBER(Base_Original!I3),Base_Original!I3,IF(RIGHT(Base_Original!I3,7)=" moedas",VALUE(LEFT(Base_Original!I3,LEN(Base_Original!I3)-7)),Base_Original!I3)) -> N/A | O3: =IF(AND($N3>50000,$Q3="Sim"),"Negada","Aprovada") -> Aprovada | P3: =IF(AND($T3="Negada",$O3="Negada"),0,IF($B3="Ativo",$U3*8%,"0")) -> 7120 | Q3: =IF(OR(Base_Original!J3="Sim",Base_Original!J3="sim",Base_Original!J3="SIM"),"Sim",IF(OR(Base_Original!J3="Não",Base_Original!J3="não",Base_Original!J3="NÃO",Base_Original!J3="Nao"),"Não",IF(Base_Original!J3="","vazio",Base_Original!J3))) -> vazio | R3: =IF(ISNUMBER(Base_Original!K3),Base_Original!K3,IF(RIGHT(Base_Original!K3,9)=" batalhas",VALUE(LEFT(Base_Original!K3,LEN(Base_Original!K3)-9)),Base_Original!K3)) -> 26 | S3: =IF($R3="vazio","vazio",IF($R3<=10,"Baixo",IF($R3<=25,"Médio","Alto"))) -> Alto | T3: =IF(AND($S3="Alto",$Q3="Sim"),"Negada","Aprovada") -> Aprovada | U3: 89000
A4: SOL003 | B4: =IF(Base_Original!A4="","vazio",IF(Base_Original!A4="ATIVO","Ativo",IF(Base_Original!A4="INATIVO","Inativo",Base_Original!A4))) -> Ativo | C4: =PROPER(Base_Original!B4) -> Aegon Bracken | D4: 000.000.244-00 | E4: =IF($D4="","Vazio",IF(LEN(SUBSTITUTE(SUBSTITUTE($D4&"",".",""),"-",""))<>11,"Inválido","OK")) -> OK | F4: =IF($D4="","Vazio",IF(COUNTIF($D$2:$D$369,$D4)>1,"Duplicado","Único")) -> Único | G4: =IF(TRIM(Base_Original!D4)="","",SUBSTITUTE(TRIM(Base_Original!D4),"anos","")) -> 69 | H4: =IF($J4="","Vazio",DATEDIF($J4,DATE(2026,9,10),"Y")) -> 69 | I4: =IF(OR(Tabela2[[#This Row],[Idade_Padronizada]]="",Tabela2[[#This Row],[Idade_Validação]]=""),"Vazio",IF(VALUE(Tabela2[[#This Row],[Idade_Padronizada]]&"")=VALUE(Tabela2[[#This Row],[Idade_Validação]]&""),"OK","Diferente")) -> OK | J4: 20725 | K4: Correrrio | L4: =PROPER(Base_Original!G4) -> Terras Fluviais | M4: 8100 | N4: =IF(ISNUMBER(Base_Original!I4),Base_Original!I4,IF(RIGHT(Base_Original!I4,7)=" moedas",VALUE(LEFT(Base_Original!I4,LEN(Base_Original!I4)-7)),Base_Original!I4)) -> 27500 | O4: =IF(AND($N4>50000,$Q4="Sim"),"Negada","Aprovada") -> Aprovada | P4: =IF(AND($T4="Negada",$O4="Negada"),0,IF($B4="Ativo",$U4*8%,"0")) -> 5800 | Q4: =IF(OR(Base_Original!J4="Sim",Base_Original!J4="sim",Base_Original!J4="SIM"),"Sim",IF(OR(Base_Original!J4="Não",Base_Original!J4="não",Base_Original!J4="NÃO",Base_Original!J4="Nao"),"Não",IF(Base_Original!J4="","vazio",Base_Original!J4))) -> Não | R4: =IF(ISNUMBER(Base_Original!K4),Base_Original!K4,IF(RIGHT(Base_Original!K4,9)=" batalhas",VALUE(LEFT(Base_Original!K4,LEN(Base_Original!K4)-9)),Base_Original!K4)) -> 42 | S4: =IF($R4="vazio","vazio",IF($R4<=10,"Baixo",IF($R4<=25,"Médio","Alto"))) -> Alto | T4: =IF(AND($S4="Alto",$Q4="Sim"),"Negada","Aprovada") -> Aprovada | U4: 72500
A5: SOL004 | B5: =IF(Base_Original!A5="","vazio",IF(Base_Original!A5="ATIVO","Ativo",IF(Base_Original!A5="INATIVO","Inativo",Base_Original!A5))) -> Inativo | C5: =PROPER(Base_Original!B5) -> Aegon Florent | D5: 27100 | E5: =IF($D5="","Vazio",IF(LEN(SUBSTITUTE(SUBSTITUTE($D5&"",".",""),"-",""))<>11,"Inválido","OK")) -> Inválido | F5: =IF($D5="","Vazio",IF(COUNTIF($D$2:$D$369,$D5)>1,"Duplicado","Único")) -> Único | G5: =IF(TRIM(Base_Original!D5)="","",SUBSTITUTE(TRIM(Base_Original!D5),"anos","")) -> 55 | H5: =IF($J5="","Vazio",DATEDIF($J5,DATE(2026,9,10),"Y")) -> 55 | I5: =IF(OR(Tabela2[[#This Row],[Idade_Padronizada]]="",Tabela2[[#This Row],[Idade_Validação]]=""),"Vazio",IF(VALUE(Tabela2[[#This Row],[Idade_Padronizada]]&"")=VALUE(Tabela2[[#This Row],[Idade_Validação]]&""),"OK","Diferente")) -> OK | J5: 25895 | K5: Meereen | L5: =PROPER(Base_Original!G5) -> Essos | M5: 6800 | N5: =IF(ISNUMBER(Base_Original!I5),Base_Original!I5,IF(RIGHT(Base_Original!I5,7)=" moedas",VALUE(LEFT(Base_Original!I5,LEN(Base_Original!I5)-7)),Base_Original!I5)) -> 12000 | O5: =IF(AND($N5>50000,$Q5="Sim"),"Negada","Aprovada") -> Aprovada | P5: =IF(AND($T5="Negada",$O5="Negada"),0,IF($B5="Ativo",$U5*8%,"0")) -> 0 | Q5: =IF(OR(Base_Original!J5="Sim",Base_Original!J5="sim",Base_Original!J5="SIM"),"Sim",IF(OR(Base_Original!J5="Não",Base_Original!J5="não",Base_Original!J5="NÃO",Base_Original!J5="Nao"),"Não",IF(Base_Original!J5="","vazio",Base_Original!J5))) -> Não | R5: =IF(ISNUMBER(Base_Original!K5),Base_Original!K5,IF(RIGHT(Base_Original!K5,9)=" batalhas",VALUE(LEFT(Base_Original!K5,LEN(Base_Original!K5)-9)),Base_Original!K5)) -> 6 | S5: =IF($R5="vazio","vazio",IF($R5<=10,"Baixo",IF($R5<=25,"Médio","Alto"))) -> Baixo | T5: =IF(AND($S5="Alto",$Q5="Sim"),"Negada","Aprovada") -> Aprovada | U5: 11000
A6: SOL005 | B6: =IF(Base_Original!A6="","vazio",IF(Base_Original!A6="ATIVO","Ativo",IF(Base_Original!A6="INATIVO","Inativo",Base_Original!A6))) -> Ativo | C6: =PROPER(Base_Original!B6) -> Aegon Frey | D6: 000.000.338-00 | E6: =IF($D6="","Vazio",IF(LEN(SUBSTITUTE(SUBSTITUTE($D6&"",".",""),"-",""))<>11,"Inválido","OK")) -> OK | F6: =IF($D6="","Vazio",IF(COUNTIF($D$2:$D$369,$D6)>1,"Duplicado","Único")) -> Único | G6: =IF(TRIM(Base_Original!D6)="","",SUBSTITUTE(TRIM(Base_Original!D6),"anos","")) -> 56 | H6: =IF($J6="","Vazio",DATEDIF($J6,DATE(2026,9,10),"Y")) -> 56 | I6: =IF(OR(Tabela2[[#This Row],[Idade_Padronizada]]="",Tabela2[[#This Row],[Idade_Validação]]=""),"Vazio",IF(VALUE(Tabela2[[#This Row],[Idade_Padronizada]]&"")=VALUE(Tabela2[[#This Row],[Idade_Validação]]&""),"OK","Diferente")) -> OK | J6: 25525 | K6: Dorne | L6: =PROPER(Base_Original!G6) -> Dorne | M6: 11100 | N6: =IF(ISNUMBER(Base_Original!I6),Base_Original!I6,IF(RIGHT(Base_Original!I6,7)=" moedas",VALUE(LEFT(Base_Original!I6,LEN(Base_Original!I6)-7)),Base_Original!I6)) -> 63000 | O6: =IF(AND($N6>50000,$Q6="Sim"),"Negada","Aprovada") -> Aprovada | P6: =IF(AND($T6="Negada",$O6="Negada"),0,IF($B6="Ativo",$U6*8%,"0")) -> 4480 | Q6: =IF(OR(Base_Original!J6="Sim",Base_Original!J6="sim",Base_Original!J6="SIM"),"Sim",IF(OR(Base_Original!J6="Não",Base_Original!J6="não",Base_Original!J6="NÃO",Base_Original!J6="Nao"),"Não",IF(Base_Original!J6="","vazio",Base_Original!J6))) -> Não | R6: =IF(ISNUMBER(Base_Original!K6),Base_Original!K6,IF(RIGHT(Base_Original!K6,9)=" batalhas",VALUE(LEFT(Base_Original!K6,LEN(Base_Original!K6)-9)),Base_Original!K6)) -> 0 | S6: =IF($R6="vazio","vazio",IF($R6<=10,"Baixo",IF($R6<=25,"Médio","Alto"))) -> Baixo | T6: =IF(AND($S6="Alto",$Q6="Sim"),"Negada","Aprovada") -> Aprovada | U6: 56000
A7: SOL006 | B7: =IF(Base_Original!A7="","vazio",IF(Base_Original!A7="ATIVO","Ativo",IF(Base_Original!A7="INATIVO","Inativo",Base_Original!A7))) -> Inativo | C7: =PROPER(Base_Original!B7) -> Aegon Hornwood | D7: 17100 | E7: =IF($D7="","Vazio",IF(LEN(SUBSTITUTE(SUBSTITUTE($D7&"",".",""),"-",""))<>11,"Inválido","OK")) -> Inválido | F7: =IF($D7="","Vazio",IF(COUNTIF($D$2:$D$369,$D7)>1,"Duplicado","Único")) -> Único | G7: =IF(TRIM(Base_Original!D7)="","",SUBSTITUTE(TRIM(Base_Original!D7),"anos","")) -> 45 | H7: =IF($J7="","Vazio",DATEDIF($J7,DATE(2026,9,10),"Y")) -> 45 | I7: =IF(OR(Tabela2[[#This Row],[Idade_Padronizada]]="",Tabela2[[#This Row],[Idade_Validação]]=""),"Vazio",IF(VALUE(Tabela2[[#This Row],[Idade_Padronizada]]&"")=VALUE(Tabela2[[#This Row],[Idade_Validação]]&""),"OK","Diferente")) -> OK | J7: 29506 | K7: Solar do Entardecer | L7: =PROPER(Base_Original!G7) -> Terras Da Tempestade | M7: 5100 | N7: =IF(ISNUMBER(Base_Original!I7),Base_Original!I7,IF(RIGHT(Base_Original!I7,7)=" moedas",VALUE(LEFT(Base_Original!I7,LEN(Base_Original!I7)-7)),Base_Original!I7)) -> 25000 | O7: =IF(AND($N7>50000,$Q7="Sim"),"Negada","Aprovada") -> Aprovada | P7: =IF(AND($T7="Negada",$O7="Negada"),0,IF($B7="Ativo",$U7*8%,"0")) -> 0 | Q7: =IF(OR(Base_Original!J7="Sim",Base_Original!J7="sim",Base_Original!J7="SIM"),"Sim",IF(OR(Base_Original!J7="Não",Base_Original!J7="não",Base_Original!J7="NÃO",Base_Original!J7="Nao"),"Não",IF(Base_Original!J7="","vazio",Base_Original!J7))) -> Não | R7: =IF(ISNUMBER(Base_Original!K7),Base_Original!K7,IF(RIGHT(Base_Original!K7,9)=" batalhas",VALUE(LEFT(Base_Original!K7,LEN(Base_Original!K7)-9)),Base_Original!K7)) -> 29 | S7: =IF($R7="vazio","vazio",IF($R7<=10,"Baixo",IF($R7<=25,"Médio","Alto"))) -> Alto | T7: =IF(AND($S7="Alto",$Q7="Sim"),"Negada","Aprovada") -> Aprovada | U7: 88000
A8: SOL007 | B8: =IF(Base_Original!A8="","vazio",IF(Base_Original!A8="ATIVO","Ativo",IF(Base_Original!A8="INATIVO","Inativo",Base_Original!A8))) -> Ativo | C8: =PROPER(Base_Original!B8) -> Aegon Marbrand | D8: 35200 | E8: =IF($D8="","Vazio",IF(LEN(SUBSTITUTE(SUBSTITUTE($D8&"",".",""),"-",""))<>11,"Inválido","OK")) -> Inválido | F8: =IF($D8="","Vazio",IF(COUNTIF($D$2:$D$369,$D8)>1,"Duplicado","Único")) -> Único | G8: =IF(TRIM(Base_Original!D8)="","",SUBSTITUTE(TRIM(Base_Original!D8),"anos","")) -> 65 | H8: =IF($J8="","Vazio",DATEDIF($J8,DATE(2026,9,10),"Y")) -> 65 | I8: =IF(OR(Tabela2[[#This Row],[Idade_Padronizada]]="",Tabela2[[#This Row],[Idade_Validação]]=""),"Vazio",IF(VALUE(Tabela2[[#This Row],[Idade_Padronizada]]&"")=VALUE(Tabela2[[#This Row],[Idade_Validação]]&""),"OK","Diferente")) -> OK | J8: 22337 | K8: Castelo Negro | L8: =PROPER(Base_Original!G8) -> Norte | M8: 3800 | N8: =IF(ISNUMBER(Base_Original!I8),Base_Original!I8,IF(RIGHT(Base_Original!I8,7)=" moedas",VALUE(LEFT(Base_Original!I8,LEN(Base_Original!I8)-7)),Base_Original!I8)) -> 49500 | O8: =IF(AND($N8>50000,$Q8="Sim"),"Negada","Aprovada") -> Aprovada | P8: =IF(AND($T8="Negada",$O8="Negada"),0,IF($B8="Ativo",$U8*8%,"0")) -> 1240 | Q8: =IF(OR(Base_Original!J8="Sim",Base_Original!J8="sim",Base_Original!J8="SIM"),"Sim",IF(OR(Base_Original!J8="Não",Base_Original!J8="não",Base_Original!J8="NÃO",Base_Original!J8="Nao"),"Não",IF(Base_Original!J8="","vazio",Base_Original!J8))) -> Não | R8: =IF(ISNUMBER(Base_Original!K8),Base_Original!K8,IF(RIGHT(Base_Original!K8,9)=" batalhas",VALUE(LEFT(Base_Original!K8,LEN(Base_Original!K8)-9)),Base_Original!K8)) -> 16 | S8: =IF($R8="vazio","vazio",IF($R8<=10,"Baixo",IF($R8<=25,"Médio","Alto"))) -> Médio | T8: =IF(AND($S8="Alto",$Q8="Sim"),"Negada","Aprovada") -> Aprovada | U8: 15500
A9: SOL008 | B9: =IF(Base_Original!A9="","vazio",IF(Base_Original!A9="ATIVO","Ativo",IF(Base_Original!A9="INATIVO","Inativo",Base_Original!A9))) -> Ativo | C9: =PROPER(Base_Original!B9) -> Aegon Redwyne | D9: 000.000.347-00 | E9: =IF($D9="","Vazio",IF(LEN(SUBSTITUTE(SUBSTITUTE($D9&"",".",""),"-",""))<>11,"Inválido","OK")) -> OK | F9: =IF($D9="","Vazio",IF(COUNTIF($D$2:$D$369,$D9)>1,"Duplicado","Único")) -> Único | G9: =IF(TRIM(Base_Original!D9)="","",SUBSTITUTE(TRIM(Base_Original!D9),"anos","")) -> 19 | H9: =IF($J9="","Vazio",DATEDIF($J9,DATE(2026,9,10),"Y")) -> 19 | I9: =IF(OR(Tabela2[[#This Row],[Idade_Padronizada]]="",Tabela2[[#This Row],[Idade_Validação]]=""),"Vazio",IF(VALUE(Tabela2[[#This Row],[Idade_Padronizada]]&"")=VALUE(Tabela2[[#This Row],[Idade_Validação]]&""),"OK","Diferente")) -> OK | J9: 39016 | K9: Pyke | L9: =PROPER(Base_Original!G9) -> Ilhas De Ferro | M9: 14900 | N9: =IF(ISNUMBER(Base_Original!I9),Base_Original!I9,IF(RIGHT(Base_Original!I9,7)=" moedas",VALUE(LEFT(Base_Original!I9,LEN(Base_Original!I9)-7)),Base_Original!I9)) -> 17000 | O9: =IF(AND($N9>50000,$Q9="Sim"),"Negada","Aprovada") -> Aprovada | P9: =IF(AND($T9="Negada",$O9="Negada"),0,IF($B9="Ativo",$U9*8%,"0")) -> 2360 | Q9: =IF(OR(Base_Original!J9="Sim",Base_Original!J9="sim",Base_Original!J9="SIM"),"Sim",IF(OR(Base_Original!J9="Não",Base_Original!J9="não",Base_Original!J9="NÃO",Base_Original!J9="Nao"),"Não",IF(Base_Original!J9="","vazio",Base_Original!J9))) -> Não | R9: =IF(ISNUMBER(Base_Original!K9),Base_Original!K9,IF(RIGHT(Base_Original!K9,9)=" batalhas",VALUE(LEFT(Base_Original!K9,LEN(Base_Original!K9)-9)),Base_Original!K9)) -> 20 | S9: =IF($R9="vazio","vazio",IF($R9<=10,"Baixo",IF($R9<=25,"Médio","Alto"))) -> Médio | T9: =IF(AND($S9="Alto",$Q9="Sim"),"Negada","Aprovada") -> Aprovada | U9: 29500
A10: SOL009 | B10: =IF(Base_Original!A10="","vazio",IF(Base_Original!A10="ATIVO","Ativo",IF(Base_Original!A10="INATIVO","Inativo",Base_Original!A10))) -> Inativo | C10: =PROPER(Base_Original!B10) -> Aegon Umber | D10: 000.000.356-00 | E10: =IF($D10="","Vazio",IF(LEN(SUBSTITUTE(SUBSTITUTE($D10&"",".",""),"-",""))<>11,"Inválido","OK")) -> OK | F10: =IF($D10="","Vazio",IF(COUNTIF($D$2:$D$369,$D10)>1,"Duplicado","Único")) -> Único | G10: =IF(TRIM(Base_Original!D10)="","",SUBSTITUTE(TRIM(Base_Original!D10),"anos","")) -> 66 | H10: =IF($J10="","Vazio",DATEDIF($J10,DATE(2026,9,10),"Y")) -> 66 | I10: =IF(OR(Tabela2[[#This Row],[Idade_Padronizada]]="",Tabela2[[#This Row],[Idade_Validação]]=""),"Vazio",IF(VALUE(Tabela2[[#This Row],[Idade_Padronizada]]&"")=VALUE(Tabela2[[#This Row],[Idade_Validação]]&""),"OK","Diferente")) -> OK | J10: 22101 | K10: Meereen | L10: =PROPER(Base_Original!G10) -> Essos | M10: 16800 | N10: =IF(ISNUMBER(Base_Original!I10),Base_Original!I10,IF(RIGHT(Base_Original!I10,7)=" moedas",VALUE(LEFT(Base_Original!I10,LEN(Base_Original!I10)-7)),Base_Original!I10)) -> 79500 | O10: =IF(AND($N10>50000,$Q10="Sim"),"Negada","Aprovada") -> Aprovada | P10: =IF(AND($T10="Negada",$O10="Negada"),0,IF($B10="Ativo",$U10*8%,"0")) -> 0 | Q10: =IF(OR(Base_Original!J10="Sim",Base_Original!J10="sim",Base_Original!J10="SIM"),"Sim",IF(OR(Base_Original!J10="Não",Base_Original!J10="não",Base_Original!J10="NÃO",Base_Original!J10="Nao"),"Não",IF(Base_Original!J10="","vazio",Base_Original!J10))) -> Não | R10: =IF(ISNUMBER(Base_Original!K10),Base_Original!K10,IF(RIGHT(Base_Original!K10,9)=" batalhas",VALUE(LEFT(Base_Original!K10,LEN(Base_Original!K10)-9)),Base_Original!K10)) -> 36 | S10: =IF($R10="vazio","vazio",IF($R10<=10,"Baixo",IF($R10<=25,"Médio","Alto"))) -> Alto | T10: =IF(AND($S10="Alto",$Q10="Sim"),"Negada","Aprovada") -> Aprovada | U10: 1500
A11: SOL010 | B11: =IF(Base_Original!A11="","vazio",IF(Base_Original!A11="ATIVO","Ativo",IF(Base_Original!A11="INATIVO","Inativo",Base_Original!A11))) -> Ativo | C11: =PROPER(Base_Original!B11) -> Arya Marbrand | D11: 000.000.133-00 | E11: =IF($D11="","Vazio",IF(LEN(SUBSTITUTE(SUBSTITUTE($D11&"",".",""),"-",""))<>11,"Inválido","OK")) -> OK | F11: =IF($D11="","Vazio",IF(COUNTIF($D$2:$D$369,$D11)>1,"Duplicado","Único")) -> Único | G11: =IF(TRIM(Base_Original!D11)="","",SUBSTITUTE(TRIM(Base_Original!D11),"anos","")) -> 24 | H11: =IF($J11="","Vazio",DATEDIF($J11,DATE(2026,9,10),"Y")) -> 24 | I11: =IF(OR(Tabela2[[#This Row],[Idade_Padronizada]]="",Tabela2[[#This Row],[Idade_Validação]]=""),"Vazio",IF(VALUE(Tabela2[[#This Row],[Idade_Padronizada]]&"")=VALUE(Tabela2[[#This Row],[Idade_Validação]]&""),"OK","Diferente")) -> OK | J11: 37172 | K11: Ninho da Águia | L11: =PROPER(Base_Original!G11) -> Vale | M11: 21600 | N11: =IF(ISNUMBER(Base_Original!I11),Base_Original!I11,IF(RIGHT(Base_Original!I11,7)=" moedas",VALUE(LEFT(Base_Original!I11,LEN(Base_Original!I11)-7)),Base_Original!I11)) -> 25000 | O11: =IF(AND($N11>50000,$Q11="Sim"),"Negada","Aprovada") -> Aprovada | P11: =IF(AND($T11="Negada",$O11="Negada"),0,IF($B11="Ativo",$U11*8%,"0")) -> 1400 | Q11: =IF(OR(Base_Original!J11="Sim",Base_Original!J11="sim",Base_Original!J11="SIM"),"Sim",IF(OR(Base_Original!J11="Não",Base_Original!J11="não",Base_Original!J11="NÃO",Base_Original!J11="Nao"),"Não",IF(Base_Original!J11="","vazio",Base_Original!J11))) -> Não | R11: =IF(ISNUMBER(Base_Original!K11),Base_Original!K11,IF(RIGHT(Base_Original!K11,9)=" batalhas",VALUE(LEFT(Base_Original!K11,LEN(Base_Original!K11)-9)),Base_Original!K11)) -> 33 | S11: =IF($R11="vazio","vazio",IF($R11<=10,"Baixo",IF($R11<=25,"Médio","Alto"))) -> Alto | T11: =IF(AND($S11="Alto",$Q11="Sim"),"Negada","Aprovada") -> Aprovada | U11: 17500
A12: SOL011 | B12: =IF(Base_Original!A12="","vazio",IF(Base_Original!A12="ATIVO","Ativo",IF(Base_Original!A12="INATIVO","Inativo",Base_Original!A12))) -> Ativo | C12: =PROPER(Base_Original!B12) -> Arya Redwyne | D12: 000.000.333-00 | E12: =IF($D12="","Vazio",IF(LEN(SUBSTITUTE(SUBSTITUTE($D12&"",".",""),"-",""))<>11,"Inválido","OK")) -> OK | F12: =IF($D12="","Vazio",IF(COUNTIF($D$2:$D$369,$D12)>1,"Duplicado","Único")) -> Único | G12: =IF(TRIM(Base_Original!D12)="","",SUBSTITUTE(TRIM(Base_Original!D12),"anos","")) -> 21 | H12: =IF($J12="","Vazio",DATEDIF($J12,DATE(2026,9,10),"Y")) -> 21 | I12: =IF(OR(Tabela2[[#This Row],[Idade_Padronizada]]="",Tabela2[[#This Row],[Idade_Validação]]=""),"Vazio",IF(VALUE(Tabela2[[#This Row],[Idade_Padronizada]]&"")=VALUE(Tabela2[[#This Row],[Idade_Validação]]&""),"OK","Diferente")) -> OK | J12: 38323 | K12: Correrrio | L12: =PROPER(Base_Original!G12) -> Terras Fluviais | M12: 3800 | N12: 0 | O12: =IF(AND($N12>50000,$Q12="Sim"),"Negada","Aprovada") -> Aprovada | P12: =IF(AND($T12="Negada",$O12="Negada"),0,IF($B12="Ativo",$U12*8%,"0")) -> 4000 | Q12: =IF(OR(Base_Original!J12="Sim",Base_Original!J12="sim",Base_Original!J12="SIM"),"Sim",IF(OR(Base_Original!J12="Não",Base_Original!J12="não",Base_Original!J12="NÃO",Base_Original!J12="Nao"),"Não",IF(Base_Original!J12="","vazio",Base_Original!J12))) -> Não | R12: =IF(ISNUMBER(Base_Original!K12),Base_Original!K12,IF(RIGHT(Base_Original!K12,9)=" batalhas",VALUE(LEFT(Base_Original!K12,LEN(Base_Original!K12)-9)),Base_Original!K12)) -> 25 | S12: =IF($R12="vazio","vazio",IF($R12<=10,"Baixo",IF($R12<=25,"Médio","Alto"))) -> Médio | T12: =IF(AND($S12="Alto",$Q12="Sim"),"Negada","Aprovada") -> Aprovada | U12: 50000
A13: SOL012 | B13: =IF(Base_Original!A13="","vazio",IF(Base_Original!A13="ATIVO","Ativo",IF(Base_Original!A13="INATIVO","Inativo",Base_Original!A13))) -> Inativo | C13: =PROPER(Base_Original!B13) -> Asha Arryn | D13: 000.000.122-00 | E13: =IF($D13="","Vazio",IF(LEN(SUBSTITUTE(SUBSTITUTE($D13&"",".",""),"-",""))<>11,"Inválido","OK")) -> OK | F13: =IF($D13="","Vazio",IF(COUNTIF($D$2:$D$369,$D13)>1,"Duplicado","Único")) -> Único | G13: =IF(TRIM(Base_Original!D13)="","",SUBSTITUTE(TRIM(Base_Original!D13),"anos","")) -> 49 | H13: =IF($J13="","Vazio",DATEDIF($J13,DATE(2026,9,10),"Y")) -> 49 | I13: =IF(OR(Tabela2[[#This Row],[Idade_Padronizada]]="",Tabela2[[#This Row],[Idade_Validação]]=""),"Vazio",IF(VALUE(Tabela2[[#This Row],[Idade_Padronizada]]&"")=VALUE(Tabela2[[#This Row],[Idade_Validação]]&""),"OK","Diferente")) -> OK | J13: 28049 | K13: Castelo Negro | L13: =PROPER(Base_Original!G13) -> Norte | M13: 25200 | N13: =IF(ISNUMBER(Base_Original!I13),Base_Original!I13,IF(RIGHT(Base_Original!I13,7)=" moedas",VALUE(LEFT(Base_Original!I13,LEN(Base_Original!I13)-7)),Base_Original!I13)) -> 59500 | O13: =IF(AND($N13>50000,$Q13="Sim"),"Negada","Aprovada") -> Aprovada | P13: =IF(AND($T13="Negada",$O13="Negada"),0,IF($B13="Ativo",$U13*8%,"0")) -> 0 | Q13: =IF(OR(Base_Original!J13="Sim",Base_Original!J13="sim",Base_Original!J13="SIM"),"Sim",IF(OR(Base_Original!J13="Não",Base_Original!J13="não",Base_Original!J13="NÃO",Base_Original!J13="Nao"),"Não",IF(Base_Original!J13="","vazio",Base_Original!J13))) -> Não | R13: =IF(ISNUMBER(Base_Original!K13),Base_Original!K13,IF(RIGHT(Base_Original!K13,9)=" batalhas",VALUE(LEFT(Base_Original!K13,LEN(Base_Original!K13)-9)),Base_Original!K13)) -> 37 | S13: =IF($R13="vazio","vazio",IF($R13<=10,"Baixo",IF($R13<=25,"Médio","Alto"))) -> Alto | T13: =IF(AND($S13="Alto",$Q13="Sim"),"Negada","Aprovada") -> Aprovada | U13: 86500
A14: SOL013 | B14: =IF(Base_Original!A14="","vazio",IF(Base_Original!A14="ATIVO","Ativo",IF(Base_Original!A14="INATIVO","Inativo",Base_Original!A14))) -> Ativo | C14: =PROPER(Base_Original!B14) -> Asha Baratheon | D14: 000.000.195-00 | E14: =IF($D14="","Vazio",IF(LEN(SUBSTITUTE(SUBSTITUTE($D14&"",".",""),"-",""))<>11,"Inválido","OK")) -> OK | F14: =IF($D14="","Vazio",IF(COUNTIF($D$2:$D$369,$D14)>1,"Duplicado","Único")) -> Único | G14: =IF(TRIM(Base_Original!D14)="","",SUBSTITUTE(TRIM(Base_Original!D14),"anos","")) -> 70 | H14: =IF($J14="","Vazio",DATEDIF($J14,DATE(2026,9,10),"Y")) -> 70 | I14: =IF(OR(Tabela2[[#This Row],[Idade_Padronizada]]="",Tabela2[[#This Row],[Idade_Validação]]=""),"Vazio",IF(VALUE(Tabela2[[#This Row],[Idade_Padronizada]]&"")=VALUE(Tabela2[[#This Row],[Idade_Validação]]&""),"OK","Diferente")) -> OK | J14: 20570 | K14: Braavos | L14: =PROPER(Base_Original!G14) -> Essos | M14: 16300 | N14: =IF(ISNUMBER(Base_Original!I14),Base_Original!I14,IF(RIGHT(Base_Original!I14,7)=" moedas",VALUE(LEFT(Base_Original!I14,LEN(Base_Original!I14)-7)),Base_Original!I14)) -> 16500 | O14: =IF(AND($N14>50000,$Q14="Sim"),"Negada","Aprovada") -> Aprovada | P14: =IF(AND($T14="Negada",$O14="Negada"),0,IF($B14="Ativo",$U14*8%,"0")) -> 5240 | Q14: =IF(OR(Base_Original!J14="Sim",Base_Original!J14="sim",Base_Original!J14="SIM"),"Sim",IF(OR(Base_Original!J14="Não",Base_Original!J14="não",Base_Original!J14="NÃO",Base_Original!J14="Nao"),"Não",IF(Base_Original!J14="","vazio",Base_Original!J14))) -> Não | R14: =IF(ISNUMBER(Base_Original!K14),Base_Original!K14,IF(RIGHT(Base_Original!K14,9)=" batalhas",VALUE(LEFT(Base_Original!K14,LEN(Base_Original!K14)-9)),Base_Original!K14)) -> 25 | S14: =IF($R14="vazio","vazio",IF($R14<=10,"Baixo",IF($R14<=25,"Médio","Alto"))) -> Médio | T14: =IF(AND($S14="Alto",$Q14="Sim"),"Negada","Aprovada") -> Aprovada | U14: 65500
A15: SOL014 | B15: =IF(Base_Original!A15="","vazio",IF(Base_Original!A15="ATIVO","Ativo",IF(Base_Original!A15="INATIVO","Inativo",Base_Original!A15))) -> Ativo | C15: =PROPER(Base_Original!B15) -> Asha Blackwood | D15: 000.000.085-00 | E15: =IF($D15="","Vazio",IF(LEN(SUBSTITUTE(SUBSTITUTE($D15&"",".",""),"-",""))<>11,"Inválido","OK")) -> OK | F15: =IF($D15="","Vazio",IF(COUNTIF($D$2:$D$369,$D15)>1,"Duplicado","Único")) -> Único | G15: =IF(TRIM(Base_Original!D15)="","",SUBSTITUTE(TRIM(Base_Original!D15),"anos","")) -> 50 | H15: =IF($J15="","Vazio",DATEDIF($J15,DATE(2026,9,10),"Y")) -> 50 | I15: =IF(OR(Tabela2[[#This Row],[Idade_Padronizada]]="",Tabela2[[#This Row],[Idade_Validação]]=""),"Vazio",IF(VALUE(Tabela2[[#This Row],[Idade_Padronizada]]&"")=VALUE(Tabela2[[#This Row],[Idade_Validação]]&""),"OK","Diferente")) -> OK | J15: 27886 | K15: Dorne | L15: =PROPER(Base_Original!G15) -> Dorne | M15: 16100 | N15: =IF(ISNUMBER(Base_Original!I15),Base_Original!I15,IF(RIGHT(Base_Original!I15,7)=" moedas",VALUE(LEFT(Base_Original!I15,LEN(Base_Original!I15)-7)),Base_Original!I15)) -> 8000 | O15: =IF(AND($N15>50000,$Q15="Sim"),"Negada","Aprovada") -> Aprovada | P15: =IF(AND($T15="Negada",$O15="Negada"),0,IF($B15="Ativo",$U15*8%,"0")) -> 2160 | Q15: =IF(OR(Base_Original!J15="Sim",Base_Original!J15="sim",Base_Original!J15="SIM"),"Sim",IF(OR(Base_Original!J15="Não",Base_Original!J15="não",Base_Original!J15="NÃO",Base_Original!J15="Nao"),"Não",IF(Base_Original!J15="","vazio",Base_Original!J15))) -> Sim | R15: =IF(ISNUMBER(Base_Original!K15),Base_Original!K15,IF(RIGHT(Base_Original!K15,9)=" batalhas",VALUE(LEFT(Base_Original!K15,LEN(Base_Original!K15)-9)),Base_Original!K15)) -> 30 | S15: =IF($R15="vazio","vazio",IF($R15<=10,"Baixo",IF($R15<=25,"Médio","Alto"))) -> Alto | T15: =IF(AND($S15="Alto",$Q15="Sim"),"Negada","Aprovada") -> Negada | U15: 27000
A16: SOL015 | B16: =IF(Base_Original!A16="","vazio",IF(Base_Original!A16="ATIVO","Ativo",IF(Base_Original!A16="INATIVO","Inativo",Base_Original!A16))) -> Inativo | C16: =PROPER(Base_Original!B16) -> Asha Bolton | D16: 6900 | E16: =IF($D16="","Vazio",IF(LEN(SUBSTITUTE(SUBSTITUTE($D16&"",".",""),"-",""))<>11,"Inválido","OK")) -> Inválido | F16: =IF($D16="","Vazio",IF(COUNTIF($D$2:$D$369,$D16)>1,"Duplicado","Único")) -> Único | G16: =IF(TRIM(Base_Original!D16)="","",SUBSTITUTE(TRIM(Base_Original!D16),"anos","")) -> 51 | H16: =IF($J16="","Vazio",DATEDIF($J16,DATE(2026,9,10),"Y")) -> 51 | I16: =IF(OR(Tabela2[[#This Row],[Idade_Padronizada]]="",Tabela2[[#This Row],[Idade_Validação]]=""),"Vazio",IF(VALUE(Tabela2[[#This Row],[Idade_Padronizada]]&"")=VALUE(Tabela2[[#This Row],[Idade_Validação]]&""),"OK","Diferente")) -> OK | J16: 27590 | K16: Castelo Negro | L16: =PROPER(Base_Original!G16) -> Norte | M16: 19400 | N16: =IF(ISNUMBER(Base_Original!I16),Base_Original!I16,IF(RIGHT(Base_Original!I16,7)=" moedas",VALUE(LEFT(Base_Original!I16,LEN(Base_Original!I16)-7)),Base_Original!I16)) -> 4000 | O16: =IF(AND($N16>50000,$Q16="Sim"),"Negada","Aprovada") -> Aprovada | P16: =IF(AND($T16="Negada",$O16="Negada"),0,IF($B16="Ativo",$U16*8%,"0")) -> 0 | Q16: =IF(OR(Base_Original!J16="Sim",Base_Original!J16="sim",Base_Original!J16="SIM"),"Sim",IF(OR(Base_Original!J16="Não",Base_Original!J16="não",Base_Original!J16="NÃO",Base_Original!J16="Nao"),"Não",IF(Base_Original!J16="","vazio",Base_Original!J16))) -> Não | R16: =IF(ISNUMBER(Base_Original!K16),Base_Original!K16,IF(RIGHT(Base_Original!K16,9)=" batalhas",VALUE(LEFT(Base_Original!K16,LEN(Base_Original!K16)-9)),Base_Original!K16)) -> 30 | S16: =IF($R16="vazio","vazio",IF($R16<=10,"Baixo",IF($R16<=25,"Médio","Alto"))) -> Alto | T16: =IF(AND($S16="Alto",$Q16="Sim"),"Negada","Aprovada") -> Aprovada | U16: 38500
A17: SOL016 | B17: =IF(Base_Original!A17="","vazio",IF(Base_Original!A17="ATIVO","Ativo",IF(Base_Original!A17="INATIVO","Inativo",Base_Original!A17))) -> Ativo | C17: =PROPER(Base_Original!B17) -> Asha Hornwood | D17: 000.000.363-00 | E17: =IF($D17="","Vazio",IF(LEN(SUBSTITUTE(SUBSTITUTE($D17&"",".",""),"-",""))<>11,"Inválido","OK")) -> OK | F17: =IF($D17="","Vazio",IF(COUNTIF($D$2:$D$369,$D17)>1,"Duplicado","Único")) -> Único | G17: =IF(TRIM(Base_Original!D17)="","",SUBSTITUTE(TRIM(Base_Original!D17),"anos","")) -> 33 | H17: =IF($J17="","Vazio",DATEDIF($J17,DATE(2026,9,10),"Y")) -> 33 | I17: =IF(OR(Tabela2[[#This Row],[Idade_Padronizada]]="",Tabela2[[#This Row],[Idade_Validação]]=""),"Vazio",IF(VALUE(Tabela2[[#This Row],[Idade_Padronizada]]&"")=VALUE(Tabela2[[#This Row],[Idade_Validação]]&""),"OK","Diferente")) -> OK | J17: 34144 | K17: Pedra do Dragão | L17: =PROPER(Base_Original!G17) -> Terras Da Coroa | M17: 21500 | N17: =IF(ISNUMBER(Base_Original!I17),Base_Original!I17,IF(RIGHT(Base_Original!I17,7)=" moedas",VALUE(LEFT(Base_Original!I17,LEN(Base_Original!I17)-7)),Base_Original!I17)) -> N/A | O17: =IF(AND($N17>50000,$Q17="Sim"),"Negada","Aprovada") -> Aprovada | P17: =IF(AND($T17="Negada",$O17="Negada"),0,IF($B17="Ativo",$U17*8%,"0")) -> 4120 | Q17: =IF(OR(Base_Original!J17="Sim",Base_Original!J17="sim",Base_Original!J17="SIM"),"Sim",IF(OR(Base_Original!J17="Não",Base_Original!J17="não",Base_Original!J17="NÃO",Base_Original!J17="Nao"),"Não",IF(Base_Original!J17="","vazio",Base_Original!J17))) -> Não | R17: =IF(ISNUMBER(Base_Original!K17),Base_Original!K17,IF(RIGHT(Base_Original!K17,9)=" batalhas",VALUE(LEFT(Base_Original!K17,LEN(Base_Original!K17)-9)),Base_Original!K17)) -> 22 | S17: =IF($R17="vazio","vazio",IF($R17<=10,"Baixo",IF($R17<=25,"Médio","Alto"))) -> Médio | T17: =IF(AND($S17="Alto",$Q17="Sim"),"Negada","Aprovada") -> Aprovada | U17: 51500
A18: SOL017 | B18: =IF(Base_Original!A18="","vazio",IF(Base_Original!A18="ATIVO","Ativo",IF(Base_Original!A18="INATIVO","Inativo",Base_Original!A18))) -> Inativo | C18: =PROPER(Base_Original!B18) -> Asha Manderly | D18: 000.000.357-00 | E18: =IF($D18="","Vazio",IF(LEN(SUBSTITUTE(SUBSTITUTE($D18&"",".",""),"-",""))<>11,"Inválido","OK")) -> OK | F18: =IF($D18="","Vazio",IF(COUNTIF($D$2:$D$369,$D18)>1,"Duplicado","Único")) -> Único | G18: =IF(TRIM(Base_Original!D18)="","",SUBSTITUTE(TRIM(Base_Original!D18),"anos","")) -> 29 | H18: =IF($J18="","Vazio",DATEDIF($J18,DATE(2026,9,10),"Y")) -> 29 | I18: =IF(OR(Tabela2[[#This Row],[Idade_Padronizada]]="",Tabela2[[#This Row],[Idade_Validação]]=""),"Vazio",IF(VALUE(Tabela2[[#This Row],[Idade_Padronizada]]&"")=VALUE(Tabela2[[#This Row],[Idade_Validação]]&""),"OK","Diferente")) -> OK | J18: 35607 | K18: Ilha dos Ursos | L18: =PROPER(Base_Original!G18) -> Norte | M18: 13800 | N18: =IF(ISNUMBER(Base_Original!I18),Base_Original!I18,IF(RIGHT(Base_Original!I18,7)=" moedas",VALUE(LEFT(Base_Original!I18,LEN(Base_Original!I18)-7)),Base_Original!I18)) -> 41500 | O18: =IF(AND($N18>50000,$Q18="Sim"),"Negada","Aprovada") -> Aprovada | P18: =IF(AND($T18="Negada",$O18="Negada"),0,IF($B18="Ativo",$U18*8%,"0")) -> 0 | Q18: =IF(OR(Base_Original!J18="Sim",Base_Original!J18="sim",Base_Original!J18="SIM"),"Sim",IF(OR(Base_Original!J18="Não",Base_Original!J18="não",Base_Original!J18="NÃO",Base_Original!J18="Nao"),"Não",IF(Base_Original!J18="","vazio",Base_Original!J18))) -> Não | R18: =IF(ISNUMBER(Base_Original!K18),Base_Original!K18,IF(RIGHT(Base_Original!K18,9)=" batalhas",VALUE(LEFT(Base_Original!K18,LEN(Base_Original!K18)-9)),Base_Original!K18)) -> 34 | S18: =IF($R18="vazio","vazio",IF($R18<=10,"Baixo",IF($R18<=25,"Médio","Alto"))) -> Alto | T18: =IF(AND($S18="Alto",$Q18="Sim"),"Negada","Aprovada") -> Aprovada | U18: 66000
A19: SOL018 | B19: =IF(Base_Original!A19="","vazio",IF(Base_Original!A19="ATIVO","Ativo",IF(Base_Original!A19="INATIVO","Inativo",Base_Original!A19))) -> Ativo | C19: =PROPER(Base_Original!B19) -> Asha Redwyne | D19: 10200 | E19: =IF($D19="","Vazio",IF(LEN(SUBSTITUTE(SUBSTITUTE($D19&"",".",""),"-",""))<>11,"Inválido","OK")) -> Inválido | F19: =IF($D19="","Vazio",IF(COUNTIF($D$2:$D$369,$D19)>1,"Duplicado","Único")) -> Único | G19: =IF(TRIM(Base_Original!D19)="","",SUBSTITUTE(TRIM(Base_Original!D19),"anos","")) -> 35 | H19: =IF($J19="","Vazio",DATEDIF($J19,DATE(2026,9,10),"Y")) -> 35 | I19: =IF(OR(Tabela2[[#This Row],[Idade_Padronizada]]="",Tabela2[[#This Row],[Idade_Validação]]=""),"Vazio",IF(VALUE(Tabela2[[#This Row],[Idade_Padronizada]]&"")=VALUE(Tabela2[[#This Row],[Idade_Validação]]&""),"OK","Diferente")) -> OK | J19: 33444 | K19: Pedra do Dragão | L19: =PROPER(Base_Original!G19) -> Terras Da Coroa | M19: 8400 | N19: =IF(ISNUMBER(Base_Original!I19),Base_Original!I19,IF(RIGHT(Base_Original!I19,7)=" moedas",VALUE(LEFT(Base_Original!I19,LEN(Base_Original!I19)-7)),Base_Original!I19)) -> 62500 | O19: =IF(AND($N19>50000,$Q19="Sim"),"Negada","Aprovada") -> Aprovada | P19: =IF(AND($T19="Negada",$O19="Negada"),0,IF($B19="Ativo",$U19*8%,"0")) -> 6680 | Q19: =IF(OR(Base_Original!J19="Sim",Base_Original!J19="sim",Base_Original!J19="SIM"),"Sim",IF(OR(Base_Original!J19="Não",Base_Original!J19="não",Base_Original!J19="NÃO",Base_Original!J19="Nao"),"Não",IF(Base_Original!J19="","vazio",Base_Original!J19))) -> Não | R19: =IF(ISNUMBER(Base_Original!K19),Base_Original!K19,IF(RIGHT(Base_Original!K19,9)=" batalhas",VALUE(LEFT(Base_Original!K19,LEN(Base_Original!K19)-9)),Base_Original!K19)) -> 31 | S19: =IF($R19="vazio","vazio",IF($R19<=10,"Baixo",IF($R19<=25,"Médio","Alto"))) -> Alto | T19: =IF(AND($S19="Alto",$Q19="Sim"),"Negada","Aprovada") -> Aprovada | U19: 83500
A20: SOL019 | B20: =IF(Base_Original!A21="","vazio",IF(Base_Original!A21="ATIVO","Ativo",IF(Base_Original!A21="INATIVO","Inativo",Base_Original!A21))) -> Ativo | C20: =PROPER(Base_Original!B21) -> Asha Tallhart | D20: 8600 | E20: =IF($D20="","Vazio",IF(LEN(SUBSTITUTE(SUBSTITUTE($D20&"",".",""),"-",""))<>11,"Inválido","OK")) -> Inválido | F20: =IF($D20="","Vazio",IF(COUNTIF($D$2:$D$369,$D20)>1,"Duplicado","Único")) -> Único | G20: =IF(TRIM(Base_Original!D20)="","",SUBSTITUTE(TRIM(Base_Original!D20),"anos","")) | H20: =IF($J20="","Vazio",DATEDIF($J20,DATE(2026,9,10),"Y")) -> 38 | I20: =IF(OR(Tabela2[[#This Row],[Idade_Padronizada]]="",Tabela2[[#This Row],[Idade_Validação]]=""),"Vazio",IF(VALUE(Tabela2[[#This Row],[Idade_Padronizada]]&"")=VALUE(Tabela2[[#This Row],[Idade_Validação]]&""),"OK","Diferente")) -> Vazio | J20: 32260 | K20: Pyke | L20: =PROPER(Base_Original!G20) -> Ilhas De Ferro | M20: 19900 | N20: =IF(ISNUMBER(Base_Original!I21),Base_Original!I21,IF(RIGHT(Base_Original!I21,7)=" moedas",VALUE(LEFT(Base_Original!I21,LEN(Base_Original!I21)-7)),Base_Original!I21)) -> 55000 | O20: =IF(AND($N20>50000,$Q20="Sim"),"Negada","Aprovada") -> Aprovada | P20: =IF(AND($T20="Negada",$O20="Negada"),0,IF($B20="Ativo",$U20*8%,"0")) -> 3800 | Q20: =IF(OR(Base_Original!J21="Sim",Base_Original!J21="sim",Base_Original!J21="SIM"),"Sim",IF(OR(Base_Original!J21="Não",Base_Original!J21="não",Base_Original!J21="NÃO",Base_Original!J21="Nao"),"Não",IF(Base_Original!J21="","vazio",Base_Original!J21))) -> Não | R20: =IF(ISNUMBER(Base_Original!K21),Base_Original!K21,IF(RIGHT(Base_Original!K21,9)=" batalhas",VALUE(LEFT(Base_Original!K21,LEN(Base_Original!K21)-9)),Base_Original!K21)) -> 26 | S20: =IF($R20="vazio","vazio",IF($R20<=10,"Baixo",IF($R20<=25,"Médio","Alto"))) -> Alto | T20: =IF(AND($S20="Alto",$Q20="Sim"),"Negada","Aprovada") -> Aprovada | U20: 47500
A21: SOL020 | B21: =IF(Base_Original!A20="","vazio",IF(Base_Original!A20="ATIVO","Ativo",IF(Base_Original!A20="INATIVO","Inativo",Base_Original!A20))) -> Ativo | C21: =PROPER(Base_Original!B20) -> Asha Tallhart | D21: 000.000.006-00 | E21: =IF($D21="","Vazio",IF(LEN(SUBSTITUTE(SUBSTITUTE($D21&"",".",""),"-",""))<>11,"Inválido","OK")) -> OK | F21: =IF($D21="","Vazio",IF(COUNTIF($D$2:$D$369,$D21)>1,"Duplicado","Único")) -> Único | G21: =IF(TRIM(Base_Original!D21)="","",SUBSTITUTE(TRIM(Base_Original!D21),"anos","")) -> 59 | H21: =IF($J21="","Vazio",DATEDIF($J21,DATE(2026,9,10),"Y")) -> 59 | I21: =IF(OR(Tabela2[[#This Row],[Idade_Padronizada]]="",Tabela2[[#This Row],[Idade_Validação]]=""),"Vazio",IF(VALUE(Tabela2[[#This Row],[Idade_Padronizada]]&"")=VALUE(Tabela2[[#This Row],[Idade_Validação]]&""),"OK","Diferente")) -> OK | J21: 24710 | K21: Correrrio | Terras Fluviais | L21: =PROPER(Base_Original!G21) | M21: 17600 | N21: =IF(ISNUMBER(Base_Original!I20),Base_Original!I20,IF(RIGHT(Base_Original!I20,7)=" moedas",VALUE(LEFT(Base_Original!I20,LEN(Base_Original!I20)-7)),Base_Original!I20)) -> 0 | O21: =IF(AND($N21>50000,$Q21="Sim"),"Negada","Aprovada") -> Aprovada | P21: =IF(AND($T21="Negada",$O21="Negada"),0,IF($B21="Ativo",$U21*8%,"0")) -> 8000 | Q21: =IF(OR(Base_Original!J20="Sim",Base_Original!J20="sim",Base_Original!J20="SIM"),"Sim",IF(OR(Base_Original!J20="Não",Base_Original!J20="não",Base_Original!J20="NÃO",Base_Original!J20="Nao"),"Não",IF(Base_Original!J20="","vazio",Base_Original!J20))) -> Sim | R21: =IF(ISNUMBER(Base_Original!K20),Base_Original!K20,IF(RIGHT(Base_Original!K20,9)=" batalhas",VALUE(LEFT(Base_Original!K20,LEN(Base_Original!K20)-9)),Base_Original!K20)) -> 31 | S21: =IF($R21="vazio","vazio",IF($R21<=10,"Baixo",IF($R21<=25,"Médio","Alto"))) -> Alto | T21: =IF(AND($S21="Alto",$Q21="Sim"),"Negada","Aprovada") -> Negada | U21: 100000
A22: SOL021 | B22: =IF(Base_Original!A22="","vazio",IF(Base_Original!A22="ATIVO","Ativo",IF(Base_Original!A22="INATIVO","Inativo",Base_Original!A22))) -> Ativo | C22: =PROPER(Base_Original!B22) -> Beric Karstark | D22: 000.000.172-00 | E22: =IF($D22="","Vazio",IF(LEN(SUBSTITUTE(SUBSTITUTE($D22&"",".",""),"-",""))<>11,"Inválido","OK")) -> OK | F22: =IF($D22="","Vazio",IF(COUNTIF($D$2:$D$369,$D22)>1,"Duplicado","Único")) -> Único | G22: =IF(TRIM(Base_Original!D22)="","",SUBSTITUTE(TRIM(Base_Original!D22),"anos","")) -> 37 | H22: =IF($J22="","Vazio",DATEDIF($J22,DATE(2026,9,10),"Y")) -> 37 | I22: =IF(OR(Tabela2[[#This Row],[Idade_Padronizada]]="",Tabela2[[#This Row],[Idade_Validação]]=""),"Vazio",IF(VALUE(Tabela2[[#This Row],[Idade_Padronizada]]&"")=VALUE(Tabela2[[#This Row],[Idade_Validação]]&""),"OK","Diferente")) -> OK | J22: 32680 | K22: Braavos | L22: =PROPER(Base_Original!G22) -> Essos | M22: 28900 | N22: =IF(ISNUMBER(Base_Original!I22),Base_Original!I22,IF(RIGHT(Base_Original!I22,7)=" moedas",VALUE(LEFT(Base_Original!I22,LEN(Base_Original!I22)-7)),Base_Original!I22)) -> 71000 | O22: =IF(AND($N22>50000,$Q22="Sim"),"Negada","Aprovada") -> Aprovada | P22: =IF(AND($T22="Negada",$O22="Negada"),0,IF($B22="Ativo",$U22*8%,"0")) -> 2920 | Q22: =IF(OR(Base_Original!J22="Sim",Base_Original!J22="sim",Base_Original!J22="SIM"),"Sim",IF(OR(Base_Original!J22="Não",Base_Original!J22="não",Base_Original!J22="NÃO",Base_Original!J22="Nao"),"Não",IF(Base_Original!J22="","vazio",Base_Original!J22))) -> Não | R22: =IF(ISNUMBER(Base_Original!K22),Base_Original!K22,IF(RIGHT(Base_Original!K22,9)=" batalhas",VALUE(LEFT(Base_Original!K22,LEN(Base_Original!K22)-9)),Base_Original!K22)) -> 28 | S22: =IF($R22="vazio","vazio",IF($R22<=10,"Baixo",IF($R22<=25,"Médio","Alto"))) -> Alto | T22: =IF(AND($S22="Alto",$Q22="Sim"),"Negada","Aprovada") -> Aprovada | U22: 36500
A23: SOL022 | B23: =IF(Base_Original!A23="","vazio",IF(Base_Original!A23="ATIVO","Ativo",IF(Base_Original!A23="INATIVO","Inativo",Base_Original!A23))) -> Ativo | C23: =PROPER(Base_Original!B23) -> Beric Umber | E23: =IF($D23="","Vazio",IF(LEN(SUBSTITUTE(SUBSTITUTE($D23&"",".",""),"-",""))<>11,"Inválido","OK")) -> Vazio | F23: =IF($D23="","Vazio",IF(COUNTIF($D$2:$D$369,$D23)>1,"Duplicado","Único")) -> Vazio | G23: =IF(TRIM(Base_Original!D23)="","",SUBSTITUTE(TRIM(Base_Original!D23),"anos","")) -> 73 | H23: =IF($J23="","Vazio",DATEDIF($J23,DATE(2026,9,10),"Y")) -> 73 | I23: =IF(OR(Tabela2[[#This Row],[Idade_Padronizada]]="",Tabela2[[#This Row],[Idade_Validação]]=""),"Vazio",IF(VALUE(Tabela2[[#This Row],[Idade_Padronizada]]&"")=VALUE(Tabela2[[#This Row],[Idade_Validação]]&""),"OK","Diferente")) -> OK | J23: 19538 | K23: Pedra do Dragão | L23: =PROPER(Base_Original!G23) -> Terras Da Coroa | M23: 12700 | N23: =IF(ISNUMBER(Base_Original!I23),Base_Original!I23,IF(RIGHT(Base_Original!I23,7)=" moedas",VALUE(LEFT(Base_Original!I23,LEN(Base_Original!I23)-7)),Base_Original!I23)) -> 79500 | O23: =IF(AND($N23>50000,$Q23="Sim"),"Negada","Aprovada") -> Aprovada | P23: =IF(AND($T23="Negada",$O23="Negada"),0,IF($B23="Ativo",$U23*8%,"0")) -> 3120 | Q23: =IF(OR(Base_Original!J23="Sim",Base_Original!J23="sim",Base_Original!J23="SIM"),"Sim",IF(OR(Base_Original!J23="Não",Base_Original!J23="não",Base_Original!J23="NÃO",Base_Original!J23="Nao"),"Não",IF(Base_Original!J23="","vazio",Base_Original!J23))) -> Não | R23: =IF(ISNUMBER(Base_Original!K23),Base_Original!K23,IF(RIGHT(Base_Original!K23,9)=" batalhas",VALUE(LEFT(Base_Original!K23,LEN(Base_Original!K23)-9)),Base_Original!K23)) -> 35 | S23: =IF($R23="vazio","vazio",IF($R23<=10,"Baixo",IF($R23<=25,"Médio","Alto"))) -> Alto | T23: =IF(AND($S23="Alto",$Q23="Sim"),"Negada","Aprovada") -> Aprovada | U23: 39000
A24: SOL023 | B24: =IF(Base_Original!A24="","vazio",IF(Base_Original!A24="ATIVO","Ativo",IF(Base_Original!A24="INATIVO","Inativo",Base_Original!A24))) -> Ativo | C24: =PROPER(Base_Original!B24) -> Beric Crakehall | D24: 000.000.067-00 | E24: =IF($D24="","Vazio",IF(LEN(SUBSTITUTE(SUBSTITUTE($D24&"",".",""),"-",""))<>11,"Inválido","OK")) -> OK | F24: =IF($D24="","Vazio",IF(COUNTIF($D$2:$D$369,$D24)>1,"Duplicado","Único")) -> Único | G24: =IF(TRIM(Base_Original!D24)="","",SUBSTITUTE(TRIM(Base_Original!D24),"anos","")) -> 55 | H24: =IF($J24="","Vazio",DATEDIF($J24,DATE(2026,9,10),"Y")) -> 55 | I24: =IF(OR(Tabela2[[#This Row],[Idade_Padronizada]]="",Tabela2[[#This Row],[Idade_Validação]]=""),"Vazio",IF(VALUE(Tabela2[[#This Row],[Idade_Padronizada]]&"")=VALUE(Tabela2[[#This Row],[Idade_Validação]]&""),"OK","Diferente")) -> OK | J24: 26104 | K24: Pyke | L24: =PROPER(Base_Original!G24) -> Ilhas De Ferro | M24: 22100 | N24: =IF(ISNUMBER(Base_Original!I24),Base_Original!I24,IF(RIGHT(Base_Original!I24,7)=" moedas",VALUE(LEFT(Base_Original!I24,LEN(Base_Original!I24)-7)),Base_Original!I24)) -> 41500 | O24: =IF(AND($N24>50000,$Q24="Sim"),"Negada","Aprovada") -> Aprovada | P24: =IF(AND($T24="Negada",$O24="Negada"),0,IF($B24="Ativo",$U24*8%,"0")) -> 5200 | Q24: =IF(OR(Base_Original!J24="Sim",Base_Original!J24="sim",Base_Original!J24="SIM"),"Sim",IF(OR(Base_Original!J24="Não",Base_Original!J24="não",Base_Original!J24="NÃO",Base_Original!J24="Nao"),"Não",IF(Base_Original!J24="","vazio",Base_Original!J24))) -> Não | R24: =IF(ISNUMBER(Base_Original!K24),Base_Original!K24,IF(RIGHT(Base_Original!K24,9)=" batalhas",VALUE(LEFT(Base_Original!K24,LEN(Base_Original!K24)-9)),Base_Original!K24)) -> 18 | S24: =IF($R24="vazio","vazio",IF($R24<=10,"Baixo",IF($R24<=25,"Médio","Alto"))) -> Médio | T24: =IF(AND($S24="Alto",$Q24="Sim"),"Negada","Aprovada") -> Aprovada | U24: 65000
A25: SOL024 | B25: =IF(Base_Original!A25="","vazio",IF(Base_Original!A25="ATIVO","Ativo",IF(Base_Original!A25="INATIVO","Inativo",Base_Original!A25))) -> Inativo | C25: =PROPER(Base_Original!B25) -> Beric Manderly | D25: 24300 | E25: =IF($D25="","Vazio",IF(LEN(SUBSTITUTE(SUBSTITUTE($D25&"",".",""),"-",""))<>11,"Inválido","OK")) -> Inválido | F25: =IF($D25="","Vazio",IF(COUNTIF($D$2:$D$369,$D25)>1,"Duplicado","Único")) -> Único | G25: =IF(TRIM(Base_Original!D25)="","",SUBSTITUTE(TRIM(Base_Original!D25),"anos","")) -> 25 | H25: =IF($J25="","Vazio",DATEDIF($J25,DATE(2026,9,10),"Y")) -> 25 | I25: =IF(OR(Tabela2[[#This Row],[Idade_Padronizada]]="",Tabela2[[#This Row],[Idade_Validação]]=""),"Vazio",IF(VALUE(Tabela2[[#This Row],[Idade_Padronizada]]&"")=VALUE(Tabela2[[#This Row],[Idade_Validação]]&""),"OK","Diferente")) -> OK | J25: 37131 | K25: Lannisporto | L25: =PROPER(Base_Original!G25) -> Oeste | M25: 24500 | N25: =IF(ISNUMBER(Base_Original!I25),Base_Original!I25,IF(RIGHT(Base_Original!I25,7)=" moedas",VALUE(LEFT(Base_Original!I25,LEN(Base_Original!I25)-7)),Base_Original!I25)) -> N/A | O25: =IF(AND($N25>50000,$Q25="Sim"),"Negada","Aprovada") -> Aprovada | P25: =IF(AND($T25="Negada",$O25="Negada"),0,IF($B25="Ativo",$U25*8%,"0")) -> 0 | Q25: =IF(OR(Base_Original!J25="Sim",Base_Original!J25="sim",Base_Original!J25="SIM"),"Sim",IF(OR(Base_Original!J25="Não",Base_Original!J25="não",Base_Original!J25="NÃO",Base_Original!J25="Nao"),"Não",IF(Base_Original!J25="","vazio",Base_Original!J25))) -> 0 | R25: =IF(ISNUMBER(Base_Original!K25),Base_Original!K25,IF(RIGHT(Base_Original!K25,9)=" batalhas",VALUE(LEFT(Base_Original!K25,LEN(Base_Original!K25)-9)),Base_Original!K25)) -> 0 | S25: =IF($R25="vazio","vazio",IF($R25<=10,"Baixo",IF($R25<=25,"Médio","Alto"))) -> Baixo | T25: =IF(AND($S25="Alto",$Q25="Sim"),"Negada","Aprovada") -> Aprovada | U25: 55000
A26: SOL025 | B26: =IF(Base_Original!A26="","vazio",IF(Base_Original!A26="ATIVO","Ativo",IF(Base_Original!A26="INATIVO","Inativo",Base_Original!A26))) -> Ativo | C26: =PROPER(Base_Original!B26) -> Beric Seaworth | D26: 000.000.025-00 | E26: =IF($D26="","Vazio",IF(LEN(SUBSTITUTE(SUBSTITUTE($D26&"",".",""),"-",""))<>11,"Inválido","OK")) -> OK | F26: =IF($D26="","Vazio",IF(COUNTIF($D$2:$D$369,$D26)>1,"Duplicado","Único")) -> Único | G26: =IF(TRIM(Base_Original!D26)="","",SUBSTITUTE(TRIM(Base_Original!D26),"anos","")) -> 72 | H26: =IF($J26="","Vazio",DATEDIF($J26,DATE(2026,9,10),"Y")) -> 72 | I26: =IF(OR(Tabela2[[#This Row],[Idade_Padronizada]]="",Tabela2[[#This Row],[Idade_Validação]]=""),"Vazio",IF(VALUE(Tabela2[[#This Row],[Idade_Padronizada]]&"")=VALUE(Tabela2[[#This Row],[Idade_Validação]]&""),"OK","Diferente")) -> OK | J26: 19800 | K26: Correrrio | L26: =PROPER(Base_Original!G26) -> Terras Fluviais | M26: 24300 | N26: =IF(ISNUMBER(Base_Original!I26),Base_Original!I26,IF(RIGHT(Base_Original!I26,7)=" moedas",VALUE(LEFT(Base_Original!I26,LEN(Base_Original!I26)-7)),Base_Original!I26)) -> 13500 | O26: =IF(AND($N26>50000,$Q26="Sim"),"Negada","Aprovada") -> Aprovada | P26: =IF(AND($T26="Negada",$O26="Negada"),0,IF($B26="Ativo",$U26*8%,"0")) -> 1160 | Q26: =IF(OR(Base_Original!J26="Sim",Base_Original!J26="sim",Base_Original!J26="SIM"),"Sim",IF(OR(Base_Original!J26="Não",Base_Original!J26="não",Base_Original!J26="NÃO",Base_Original!J26="Nao"),"Não",IF(Base_Original!J26="","vazio",Base_Original!J26))) -> Não | R26: =IF(ISNUMBER(Base_Original!K26),Base_Original!K26,IF(RIGHT(Base_Original!K26,9)=" batalhas",VALUE(LEFT(Base_Original!K26,LEN(Base_Original!K26)-9)),Base_Original!K26)) -> 33 | S26: =IF($R26="vazio","vazio",IF($R26<=10,"Baixo",IF($R26<=25,"Médio","Alto"))) -> Alto | T26: =IF(AND($S26="Alto",$Q26="Sim"),"Negada","Aprovada") -> Aprovada | U26: 14500
